Workbook
Name AdicoesLR: #REF!
Name AjNegativosRTT: #REF!
Name AjPositivosRTT: #REF!
Name Ano: #REF!
Name Dia: #REF!
Name Empresas: #REF!
Name ExclusoesLR: #REF!
Name Mês: #REF!
Name ReconImp: #REF!
Name WACC: DCF!$B$20

Sheet Sheet1

Sheet Cover
A1: SLC Agrícola (SLCE3) | G1: About the Company
A2: Financial model and valuation for educational purposes
B4: Tiago Cousseau | E4: May 2026
B5: LinkedIn
B8: Target Price | E8: =DCF!B38 -> 17.334818
B9: Current Price | E9: 17.5
B10: Upside | E10: =(E8-E9)/E8 -> -0.0095289361
B11: CoE | E11: =WACC -> 0.13628945
A13: Methodologies
B15: • DCF Valuation
B16: • Commodity Price Curve
B17: • FX Forecast
B18: • Planted Area Growth

Sheet DCF
A1: Discounted Cash Flow | H1: Methodologies
B2: 2026 | C2: 2027 | D2: 2028 | E2: 2029 | F2: 2030
B3: F | C3: F | D3: F | E3: F | F3: F
A4: Revenue | B4: ='Income Statement'!O18 -> 9360729 | C4: ='Income Statement'!P18 -> 11616585 | D4: ='Income Statement'!Q18 -> 12399655 | E4: ='Income Statement'!R18 -> 13848822 | F4: ='Income Statement'!S18 -> 14465023 | H4: • Expected Planted Area • Historical Yield • Commodities Curve
A6: Net Income | B6: ='Income Statement'!O69 -> 523085.83 | C6: ='Income Statement'!P69 -> 871637.21 | D6: ='Income Statement'!Q69 -> 976386.79 | E6: ='Income Statement'!R69 -> 1189460 | F6: ='Income Statement'!S69 -> 1266856.3 | H6: • Historical Crop Margin • Recent SG&A % of Revenue • Last Year Interest Rate • Historical APV lease liability/ha
A8: =_xlfn.UNICHAR(916) & " WC" -> Δ WC | B8: ='Income Statement'!O18*B9 -> 140410.94 | C8: ='Income Statement'!P18*C9 -> 174248.78 | D8: ='Income Statement'!Q18*D9 -> 185994.82 | E8: ='Income Statement'!R18*E9 -> 207732.33 | F8: ='Income Statement'!S18*F9 -> 216975.35 | H8: • Historical Geometric Mean % of revenue
A9: % of revenue Ex. | B9: 0.015 | C9: 0.015 | D9: 0.015 | E9: 0.015 | F9: 0.015
A11: Maintenance Capex | B11: ='▲ PPE'!AC118 -> 385111.08 | C11: ='▲ PPE'!AD118 -> 404366.63 | D11: ='▲ PPE'!AE118 -> 424584.97 | E11: ='▲ PPE'!AF118 -> 445814.21 | F11: ='▲ PPE'!AG118 -> 468104.92 | H11: • Recent Maintenance Capex / ha
A12: R$/ha | B12: 0.4 | C12: 0.4 | D12: 0.4 | E12: 0.4 | F12: 0.4
A14: Expansion Capex | B14: ='▲ PPE'!AC138 -> 346599.97 | C14: ='▲ PPE'!AD138 -> 363929.97 | D14: ='▲ PPE'!AE138 -> 382126.47 | E14: ='▲ PPE'!AF138 -> 401232.79 | F14: ='▲ PPE'!AG138 -> 252776.66 | H14: • Last Year Expansion Capex / Current Planted Area Change
A15: ="Expansion CapEx t-1 /" & _xlfn.UNICHAR(916) &"ha t" -> Expansion CapEx t-1 /Δha t | B15: 7.2 | C15: 7.2 | D15: 7.2 | E15: 7.2 | F15: 7.2
A17: Depreciation | B17: ='▲ PPE'!AC33 -> 426713.1 | C17: ='▲ PPE'!AD33 -> 445012.98 | D17: ='▲ PPE'!AE33 -> 464409.99 | E17: ='▲ PPE'!AF33 -> 484948.08 | F17: ='▲ PPE'!AG33 -> 506674.02 | H17: • Recent Normalized Depreciation
A18: % of PPE | B18: 0.06 | C18: 0.06 | D18: 0.06 | E18: 0.06 | F18: 0.06
A20: Cost of Equity | B20: =CoE!O30 -> 0.13628945 | C20: =CoE!P30 -> 0.13504277 | D20: =CoE!Q30 -> 0.13374957 | E20: =CoE!R30 -> 0.13230453 | F20: =CoE!S30 -> 0.13090323 | H20: • Flat Debt • Equity Based on Retained Earnings • Damodaran Unleveraged Beta
A22: Free Cash | B22: =(B6-B8-B11-B14+B17) -> 77676.946 | C22: =(C6-C8-C11-C14+C17) -> 374104.81 | D22: =(D6-D8-D11-D14+D17) -> 448090.53 | E22: =(E6-E8-E11-E14+E17) -> 619628.75 | F22: =(F6-F8-F11-F14+F17) -> 835673.43
A24: Discounting
B26: 1 | C26: 2 | D26: 3 | E26: 4 | F26: 5
A27: Free Cash PV | B27: =IF(B22<0,0,B22/(1+B20)^B26) -> 68360.175 | C27: =IF(C22<0,0,C22/(1+C20)^C26) -> 290381.43 | D27: =IF(D22<0,0,D22/(1+D20)^D26) -> 307478.22 | E27: =IF(E22<0,0,E22/(1+E20)^E26) -> 376945.52 | F27: =IF(F22<0,0,F22/(1+F20)^F26) -> 451761.66
A28: Perpetuity | F28: =(F22*(1+B31))/(F20-B31) -> 8530387.3
A29: Perpetuity PV | F29: =F28/(DCF!B20+1)^F26 -> 4503227.3
A31: Terminal Growth | B31: 0.03
A33: Equity Value | B33: =SUM(B27:F27,F29) -> 5998154.3
A34: Cash and Cash Equivalents | B34: ='Balance Sheet'!N4 -> 2647586
A36: Shares | B36: 498750
A38: Equity per Share | B38: =SUM(B33:B34)/B36 -> 17.334818

Sheet Income Statement
A1: Income Statement
A2: (R$ thud) | B2: 2013 | C2: =SUM(B2+1) -> 2014 | D2: =SUM(C2+1) -> 2015 | E2: =SUM(D2+1) -> 2016 | F2: =SUM(E2+1) -> 2017 | G2: =SUM(F2+1) -> 2018 | H2: =SUM(G2+1) -> 2019 | I2: =SUM(H2+1) -> 2020 | J2: =SUM(I2+1) -> 2021 | ... S2: =SUM(R2+1) -> 2030
B3: A | C3: A | D3: A | E3: A | F3: A | G3: A | H3: A | I3: A | J3: A | K3: A | L3: A | M3: A | N3: A | O3: F | P3: F | Q3: F | R3: F | S3: F
A4: REVENUE
A5: Cotton lint | B5: 553635 | C5: 652524 | D5: 812693 | E5: 749417 | F5: 745772 | G5: 1088621 | H5: 1212573 | I5: 1697671 | J5: 2087461 | K5: 2930972 | L5: 2189209 | M5: 3568362 | N5: 3344618 | O5: =('Income by Crop'!O5*'Income by Crop'!O9)/1000 -> 3914909.8 | P5: =('Income by Crop'!P5*'Income by Crop'!P9)/1000 -> 4984930.9 | Q5: =('Income by Crop'!Q5*'Income by Crop'!Q9)/1000 -> 5133580.7 | R5: =('Income by Crop'!R5*'Income by Crop'!R9)/1000 -> 5756454.1 | S5: =('Income by Crop'!S5*'Income by Crop'!S9)/1000 -> 5942842.9
A6: Cottonseed | B6: 83077 | C6: 82043 | D6: 85019 | E6: 98902 | F6: 104375 | G6: 80496 | H6: 77154 | I6: 156269 | J6: 348928 | K6: 380070 | L6: 349283 | M6: 320811 | N6: 386901 | O6: =('Income by Crop'!O18*'Income by Crop'!O20)/1000 -> 462087.71 | P6: =('Income by Crop'!P18*'Income by Crop'!P20)/1000 -> 588385.29 | Q6: =('Income by Crop'!Q18*'Income by Crop'!Q20)/1000 -> 605930.84 | R6: =('Income by Crop'!R18*'Income by Crop'!R20)/1000 -> 679450.32 | S6: =('Income by Crop'!S18*'Income by Crop'!S20)/1000 -> 701450.31
A7: Soybean | B7: 328348 | C7: 478022 | D7: 634055 | E7: 583990 | F7: 720879 | G7: 875235 | H7: 1036218 | I7: 1291803 | J7: 1673697 | K7: 2973363 | L7: 3055726 | M7: 2092605 | N7: 2749065 | O7: =('Income by Crop'!O32*'Income by Crop'!O36)/1000 -> 3551190.7 | P7: =('Income by Crop'!P32*'Income by Crop'!P36)/1000 -> 4372079.8 | Q7: =('Income by Crop'!Q32*'Income by Crop'!Q36)/1000 -> 4783138.7 | R7: =('Income by Crop'!R32*'Income by Crop'!R36)/1000 -> 5349944.9 | S7: =('Income by Crop'!S32*'Income by Crop'!S36)/1000 -> 5645529.4
A8: Corn | B8: 99224 | C8: 111950 | D8: 121877 | E8: 164514 | F8: 152733 | G8: 146151 | H8: 253376 | I8: 383504 | J8: 518078 | K8: 710473 | L8: 846036 | M8: 523883 | N8: 1035234 | O8: =('Income by Crop'!O45*'Income by Crop'!O49)/1000 -> 1125058.2 | P8: =('Income by Crop'!P45*'Income by Crop'!P49)/1000 -> 1368615.6 | Q8: =('Income by Crop'!Q45*'Income by Crop'!Q49)/1000 -> 1559302.2 | R8: =('Income by Crop'!R45*'Income by Crop'!R49)/1000 -> 1729385.1 | S8: =('Income by Crop'!S45*'Income by Crop'!S49)/1000 -> 1824933.6
A9: Coffee | B9: 9145 | C9: 5334
A10: Sugarcane | C10: 2556
A11: Cattle Herd | I11: 29528 | J11: 59377 | K11: 110862 | L11: 121007 | M11: 202280 | N11: 383851 | O11: =('Income by Crop'!O60*'Income by Crop'!O64)/1000 -> 307482.62 | P11: =('Income by Crop'!P60*'Income by Crop'!P64)/1000 -> 302573.61 | Q11: =('Income by Crop'!Q60*'Income by Crop'!Q64)/1000 -> 317702.29 | R11: =('Income by Crop'!R60*'Income by Crop'!R64)/1000 -> 333587.41 | S11: =('Income by Crop'!S60*'Income by Crop'!S64)/1000 -> 350266.78
A12: Seeds | N12: 296096
A13: Others | B13: 15421 | C13: 29894 | D13: 59480 | E13: 26361 | F13: 23141 | G13: 39483 | H13: 72874 | I13: 70379 | J13: 261620 | K13: 272919 | L13: 61390 | M13: 92968 | N13: 129120
A15: Hedge Result | B15: -53622 | C15: -26319 | D15: =-231373 -> -231373 | E15: -21239 | F15: 111154 | G15: -130809 | H15: =-116290 -> -116290 | I15: -531607 | J15: =-585951 -> -585951 | K15: -5625 | L15: 607932 | M15: 114855 | N15: 228262
A16: Biological Assets | B16: 146292 | C16: 163171 | D16: 279830 | E16: 57704 | F16: 361847 | G16: 724291 | H16: 504751 | I16: 775534 | J16: 1961159 | K16: 2216676 | L16: 1891541 | M16: 887863 | N16: 1206067
A18: Revenue Ex. Biological Assets | B18: =SUM(B5:B15) -> 1035228 | C18: =SUM(C5:C15) -> 1336004 | D18: =SUM(D5:D15) -> 1481751 | E18: =SUM(E5:E15) -> 1601945 | F18: =SUM(F5:F15) -> 1858054 | G18: =SUM(G5:G15) -> 2099177 | H18: =SUM(H5:H15) -> 2535905 | I18: =SUM(I5:I15) -> 3097547 | ... N18: =SUM(N5:N15) -> 8553147 | O18: =SUM(O5:O16) -> 9360729 | P18: =SUM(P5:P16) -> 11616585 | Q18: =SUM(Q5:Q16) -> 12399655 | R18: =SUM(R5:R16) -> 13848822 | S18: =SUM(S5:S16) -> 14465023
A19: Total Revenue | B19: =SUM(B5:B16) -> 1181520 | C19: =SUM(C5:C16) -> 1499175 | D19: =SUM(D5:D16) -> 1761581 | E19: =SUM(E5:E16) -> 1659649 | F19: =SUM(F5:F16) -> 2219901 | G19: =SUM(G5:G16) -> 2823468 | H19: =SUM(H5:H16) -> 3040656 | I19: =SUM(I5:I16) -> 3873081 | ... N19: =SUM(N5:N16) -> 9759214
A21: COGS
A22: Cotton lint | B22: 379091 | C22: 424043 | D22: =501326 -> 501326 | E22: 629116 | F22: =481841 -> 481841 | G22: 567966 | H22: =762874 -> 762874 | I22: 945782 | J22: =1082365 -> 1082365 | K22: 1831639 | L22: =1636704 -> 1636704 | M22: 2204939 | N22: 2343345 | O22: =('Income by Crop'!O5*'Income by Crop'!O11*-1)/1000 -> 2583840.5 | P22: =('Income by Crop'!P5*'Income by Crop'!P11*-1)/1000 -> 3290054.4 | Q22: =('Income by Crop'!Q5*'Income by Crop'!Q11*-1)/1000 -> 3388163.3 | R22: =('Income by Crop'!R5*'Income by Crop'!R11*-1)/1000 -> 3799259.7 | S22: =('Income by Crop'!S5*'Income by Crop'!S11*-1)/1000 -> 3922276.3
A23: Cottonseed | B23: 58920 | C23: 61891 | D23: =64080 -> 64080 | E23: 97913 | F23: =75483 -> 75483 | G23: 52980 | H23: =61257 -> 61257 | I23: 98128 | J23: =133245 -> 133245 | K23: 140849 | L23: =205003 -> 205003 | M23: 227896 | N23: 229100 | O23: =('Income by Crop'!O18*'Income by Crop'!O22*-1)/1000 -> 328183.9 | P23: =('Income by Crop'!P18*'Income by Crop'!P22*-1)/1000 -> 417882.95 | Q23: =('Income by Crop'!Q18*'Income by Crop'!Q22*-1)/1000 -> 430344.16 | R23: =('Income by Crop'!R18*'Income by Crop'!R22*-1)/1000 -> 482559.16 | S23: =('Income by Crop'!S18*'Income by Crop'!S22*-1)/1000 -> 498183.99
A24: Soybean | B24: 259742 | C24: 366835 | D24: =419781 -> 419781 | E24: 463229 | F24: =506506 -> 506506 | G24: 567844 | H24: =644331 -> 644331 | I24: 697641 | J24: =793574 -> 793574 | K24: 1449659 | L24: =1634559 -> 1634559 | M24: 1599801 | N24: 1772371 | O24: =('Income by Crop'!O32*'Income by Crop'!O38*-1)/1000 -> 2414809.7 | P24: =('Income by Crop'!P32*'Income by Crop'!P38*-1)/1000 -> 2973014.3 | Q24: =('Income by Crop'!Q32*'Income by Crop'!Q38*-1)/1000 -> 3252534.3 | R24: =('Income by Crop'!R32*'Income by Crop'!R38*-1)/1000 -> 3637962.6 | S24: =('Income by Crop'!S32*'Income by Crop'!S38*-1)/1000 -> 3838960
A25: Corn | B25: 90679 | C25: 90674 | D25: =81088 -> 81088 | E25: 106401 | F25: =128920 -> 128920 | G25: 133109 | H25: =198182 -> 198182 | I25: 230112 | J25: =420625 -> 420625 | K25: 542399 | L25: =693868 -> 693868 | M25: 424994 | N25: 678447 | O25: =('Income by Crop'!O45*'Income by Crop'!O51*-1)/1000 -> 765039.56 | P25: =('Income by Crop'!P45*'Income by Crop'!P51*-1)/1000 -> 930658.6 | Q25: =('Income by Crop'!Q45*'Income by Crop'!Q51*-1)/1000 -> 1060325.5 | R25: =('Income by Crop'!R45*'Income by Crop'!R51*-1)/1000 -> 1175981.9 | S25: =('Income by Crop'!S45*'Income by Crop'!S51*-1)/1000 -> 1240954.9
A26: Coffee | B26: 3392 | C26: 6032
A27: Sugarcane | C27: 927
A28: Cattle Heard | I28: 25027 | J28: =53800 -> 53800 | K28: 119413 | L28: =143966 -> 143966 | M28: 184773 | N28: 343489 | O28: =('Income by Crop'!O60*'Income by Crop'!O66*-1)/1000 -> 270798.91 | P28: =('Income by Crop'!P60*'Income by Crop'!P66*-1)/1000 -> 266475.55 | Q28: =('Income by Crop'!Q60*'Income by Crop'!Q66*-1)/1000 -> 279799.33 | R28: =('Income by Crop'!R60*'Income by Crop'!R66*-1)/1000 -> 293789.3 | S28: =('Income by Crop'!S60*'Income by Crop'!S66*-1)/1000 -> 308478.76
A29: Seeds | N29: 84832
A30: Others | B30: 14384 | C30: 23088 | D30: =34915 -> 34915 | E30: 31589 | F30: =22555 -> 22555 | G30: 36335 | H30: =66562 -> 66562 | I30: 55096 | J30: =167682 -> 167682 | K30: 136771 | L30: =100671 -> 100671 | M30: 127279 | N30: 161490
A32: Realized Biological Assets | B32: 114026 | C32: 192600 | D32: =227270 -> 227270 | E32: 84933 | F32: =327300 -> 327300 | G32: 619276 | H32: =524266 -> 524266 | I32: 750996 | J32: =1425434 -> 1425434 | K32: 2237681 | L32: =2086659 -> 2086659 | M32: 726219 | N32: 1217211
A34: COGS Ex. Biological Assets | B34: =SUM(B22:B30) -> 806208 | C34: =SUM(C22:C30) -> 973490 | D34: =SUM(D22:D30) -> 1101190 | E34: =SUM(E22:E30) -> 1328248 | F34: =SUM(F22:F30) -> 1215305 | G34: =SUM(G22:G30) -> 1358234 | H34: =SUM(H22:H30) -> 1733206 | I34: =SUM(I22:I30) -> 2051786 | ... S34: =SUM(S22:S30) -> 9808853.9
A35: Total COGS | B35: =SUM(B22:B32) -> 920234 | C35: =SUM(C22:C32) -> 1166090 | D35: =SUM(D22:D32) -> 1328460 | E35: =SUM(E22:E32) -> 1413181 | F35: =SUM(F22:F32) -> 1542605 | G35: =SUM(G22:G32) -> 1977510 | H35: =SUM(H22:H32) -> 2257472 | I35: =SUM(I22:I32) -> 2802782 | ... N35: =SUM(N22:N32) -> 6830285
A37: Gross Profit | B37: =(B19-B35) -> 261286 | C37: =(C19-C35) -> 333085 | D37: =(D19-D35) -> 433121 | E37: =(E19-E35) -> 246468 | F37: =(F19-F35) -> 677296 | G37: =(G19-G35) -> 845958 | H37: =(H19-H35) -> 783184 | I37: =(I19-I35) -> 1070299 | ... N37: =(N19-N35) -> 2928929
A38: Gross Profit Ex Bio | B38: =B18-B34 -> 229020 | C38: =C18-C34 -> 362514 | D38: =D18-D34 -> 380561 | E38: =E18-E34 -> 273697 | F38: =F18-F34 -> 642749 | G38: =G18-G34 -> 740943 | H38: =H18-H34 -> 802699 | I38: =I18-I34 -> 1045761 | ... S38: =S18-S34 -> 4656169.1
A40: Sales Expenses | B40: -63991 | C40: -85335 | D40: -92070 | E40: -97589 | F40: -90206 | G40: -118674 | H40: -152972 | I40: -173964 | J40: -212559 | K40: -379664 | L40: -388859 | M40: -495108 | N40: -632312
A41: General & Administrative (G&A) | B41: -39272 | C41: -37078 | D41: -39769 | E41: -42894 | F41: -44832 | G41: -51573 | H41: -63236 | I41: -70058 | J41: -124286 | K41: -175815 | L41: -195892 | M41: -209059 | N41: -255715
A42: Profit Sharing | B42: -8457 | C42: -16658 | D42: -18668 | E42: -16193 | F42: -41204 | G42: -49941 | H42: -39915 | I42: -60110 | J42: -117163 | K42: -108789 | L42: -112868 | M42: -82179 | N42: -85638
A43: Other Operating Income / (Expenses) | B43: 913 | C43: -3217 | D43: 2884 | E43: 20523 | F43: 92399 | G43: 31987 | H43: 31651 | I43: 14763 | J43: 134563 | K43: 64123 | L43: 12106 | M43: -8228 | N43: -142703
A45: Total SG&A | B45: =SUM(B40:B43) -> -110807 | C45: =SUM(C40:C43) -> -142288 | D45: =SUM(D40:D43) -> -147623 | E45: =SUM(E40:E43) -> -136153 | F45: =SUM(F40:F43) -> -83843 | G45: =SUM(G40:G43) -> -188201 | H45: =SUM(H40:H43) -> -224472 | I45: =SUM(I40:I43) -> -289369 | ... N45: =SUM(N40:N43) -> -1116368 | O45: =O18*O46 -> -1029680.2 | P45: =P18*P46 -> -1277824.4 | Q45: =Q18*Q46 -> -1363962 | R45: =R18*R46 -> -1523370.4 | S45: =S18*S46 -> -1591152.5
A46: % of Revenue Ex bio | B46: =B45/B18 -> -0.10703632 | C46: =C45/C18 -> -0.10650268 | D46: =D45/D18 -> -0.0996274 | E46: =E45/E18 -> -0.084992306 | F46: =F45/F18 -> -0.045124092 | G46: =G45/G18 -> -0.08965466 | H46: =H45/H18 -> -0.088517511 | I46: =I45/I18 -> -0.09341876 | ... N46: =N45/N18 -> -0.13052132 | O46: -0.11 | P46: -0.11 | Q46: -0.11 | R46: -0.11 | S46: -0.11
A48: EBIT | B48: =B37+B45 -> 150479 | C48: =C37+C45 -> 190797 | D48: =D37+D45 -> 285498 | E48: =E37+E45 -> 110315 | F48: =F37+F45 -> 593453 | G48: =G37+G45 -> 657757 | H48: =H37+H45 -> 558712 | I48: =I37+I45 -> 780930 | ... N48: =N37+N45 -> 1812561
A49: EBIT Ex Bio | B49: =B38+B45 -> 118213 | C49: =C38+C45 -> 220226 | D49: =D38+D45 -> 232938 | E49: =E38+E45 -> 137544 | F49: =F38+F45 -> 558906 | G49: =G38+G45 -> 552742 | H49: =H38+H45 -> 578227 | I49: =I38+I45 -> 756392 | ... S49: =S38+S45 -> 3065016.6
...

Sheet Planted Area
A1: Planted Area
A2: Planted Area (ha) | B2: 2013/14 | C2: 2014/15 | D2: 2015/16 | E2: 2016/17 | F2: 2017/18 | G2: 2018/19 | H2: 2019/20 | I2: 2020/21 | J2: 2021/22 | K2: 2022/23 | L2: 2023/24 | M2: 2024/25 | N2: 2025/26 | O2: 2026/27 | P2: 2027/28 | Q2: 2028/29 | R2: 2029/30 | S2: 2030/31
B3: A | C3: A | D3: A | E3: A | F3: A | G3: A | H3: A | I3: A | J3: A | K3: A | L3: A | M3: A | N3: A | O3: F | P3: F | Q3: F | R3: F | S3: F
A4: Cotton Lint 1 Crop | B4: 81019 | C4: 83680 | D4: 74404 | E4: 58886 | F4: 57832 | G4: 72852 | H4: 74054 | I4: 78011 | J4: 86357 | K4: 85823 | L4: 106698 | M4: 95460 | N4: 107464 | O4: =O16*O$11 -> 134601.01 | P4: =P16*P$11 -> 141331.06 | Q4: =Q16*Q$11 -> 148397.61 | R4: =R16*R$11 -> 155817.49 | S4: =S16*S$11 -> 163608.37
A5: Cotton Lint 2 Crop | B5: 12647 | C5: 14882 | D5: 19002 | E5: 28554 | F5: 37292 | G5: 50875 | H5: 51408 | I5: 31594 | J5: 90628 | K5: 76420 | L5: 82036 | M5: 83343 | N5: 84620 | O5: =O17*O$11 -> 108592.38 | P5: =P17*P$11 -> 114021.99 | Q5: =Q17*Q$11 -> 119723.09 | R5: =R17*R$11 -> 125709.25 | S5: =S17*S$11 -> 131994.71
A6: Soybean (commercial + seed) | B6: 184702 | C6: 208693 | D6: 212586 | E6: 230127 | F6: 230164 | G6: 243149 | H6: 235444 | I6: 229449 | J6: 334891 | K6: 346941 | L6: 320009 | M6: 377531 | N6: 424672 | O6: =O18*O$11 -> 482719.68 | P6: =P18*P$11 -> 506855.66 | Q6: =Q18*Q$11 -> 532198.44 | R6: =R18*R$11 -> 558808.37 | S6: =S18*S$11 -> 586748.79
A7: Corn 1 Crop | B7: 13575 | C7: 5127 | O7: =O19*O$11 -> 0 | P7: =P19*P$11 -> 0 | Q7: =Q19*Q$11 -> 0 | R7: =R19*R$11 -> 0 | S7: =S19*S$11 -> 0
A8: Corn 2 Crop | B8: 37190 | C8: 38280 | D8: 65681 | E8: 71790 | F8: 76931 | G8: 89311 | H8: 82392 | I8: 106470 | J8: 121633 | K8: 137585 | L8: 95167 | M8: 122748 | N8: 157370 | O8: =O20*O$11 -> 160036.23 | P8: =P20*P$11 -> 168038.04 | Q8: =Q20*Q$11 -> 176439.94 | R8: =R20*R$11 -> 185261.94 | S8: =S20*S$11 -> 194525.04
A9: Cattle Herd | I9: 3526 | J9: 4932 | K9: 3962 | L9: 5298 | M9: 5594 | N9: 8341 | O9: =O21*O$11 -> 8207.8345 | P9: =P21*P$11 -> 8618.2262 | Q9: =Q21*Q$11 -> 9049.1375 | R9: =R21*R$11 -> 9501.5944 | S9: =S21*S$11 -> 9976.6741
A10: Other | B10: 14435 | C10: 19363 | D10: 5587 | E10: 3564 | F10: 2228 | G10: 1912 | H10: 5270 | I10: 14117 | J10: 33505 | K10: 23653 | L10: 52134 | M10: 51230 | N10: 54732 | O10: =O22*O$11 -> 68620.577 | P10: =P22*P$11 -> 72051.606 | Q10: =Q22*Q$11 -> 75654.186 | R10: =R22*R$11 -> 79436.896 | S10: =S22*S$11 -> 83408.741
A11: Total | B11: =SUM(B4:B10) -> 343568 | C11: =SUM(C4:C10) -> 370025 | D11: =SUM(D4:D10) -> 377260 | E11: =SUM(E4:E10) -> 392921 | F11: =SUM(F4:F10) -> 404447 | G11: =SUM(G4:G10) -> 458099 | H11: =SUM(H4:H10) -> 448568 | I11: =SUM(I4:I10) -> 463167 | ... N11: =SUM(N4:N10) -> 837199 | O11: =O35 -> 962777.7 | P11: =P35 -> 1010916.6 | Q11: =Q35 -> 1061462.4 | R11: =R35 -> 1114535.5 | S11: =S35 -> 1170262.3
A12: Total %▲ | C12: =(C35-B35)/B35 -> 0.0770095 | D12: =(D35-C35)/C35 -> 0.01954187 | E12: =(E35-D35)/D35 -> 0.041520767 | F12: =(F35-E35)/E35 -> 0.029331596 | G12: =(G35-F35)/F35 -> 0.13265801 | H12: =(H35-G35)/G35 -> -0.020805546 | I12: =(I35-H35)/H35 -> 0.03254579 | J12: =(J35-I35)/I35 -> 0.45076398 | ... N12: =(N35-M35)/M35 -> 0.13764103 | O12: 0.15 | P12: 0.05 | Q12: 0.05 | R12: 0.05 | S12: 0.05
A15: Crop Composition
A16: Cotton Lint 1 Crop | B16: =B4/B$11 -> 0.23581649 | C16: =C4/C$11 -> 0.22614688 | D16: =D4/D$11 -> 0.19722207 | E16: =E4/E$11 -> 0.14986728 | F16: =F4/F$11 -> 0.14299031 | G16: =G4/G$11 -> 0.15903113 | H16: =H4/H$11 -> 0.1650898 | I16: =I4/I$11 -> 0.16842953 | ... N16: =N4/N$11 -> 0.12836136 | O16: 0.13980487 | P16: 0.13980487 | Q16: 0.13980487 | R16: 0.13980487 | S16: 0.13980487
A17: Cotton Lint 2 Crop | B17: =B5/B$11 -> 0.036810762 | C17: =C5/C$11 -> 0.040218904 | D17: =D5/D$11 -> 0.050368446 | E17: =E5/E$11 -> 0.072671097 | F17: =F5/F$11 -> 0.092204912 | G17: =G5/G$11 -> 0.11105678 | H17: =H5/H$11 -> 0.1146047 | I17: =I5/I$11 -> 0.068212977 | ... N17: =N5/N$11 -> 0.10107513 | O17: 0.1127907 | P17: 0.1127907 | Q17: 0.1127907 | R17: 0.1127907 | S17: 0.1127907
A18: Soybean (commercial + seed) | B18: =B6/B$11 -> 0.53759954 | C18: =C6/C$11 -> 0.56399703 | D18: =D6/D$11 -> 0.56349997 | E18: =E6/E$11 -> 0.58568262 | F18: =F6/F$11 -> 0.56908322 | G18: =G6/G$11 -> 0.53077828 | H18: =H6/H$11 -> 0.52487917 | I18: =I6/I$11 -> 0.49539151 | ... N18: =N6/N$11 -> 0.50725335 | O18: 0.50138228 | P18: 0.50138228 | Q18: 0.50138228 | R18: 0.50138228 | S18: 0.50138228
A19: Corn 1 Crop | B19: =B7/B$11 -> 0.039511829 | C19: =C7/C$11 -> 0.013855821 | D19: =D7/D$11 -> 0 | E19: =E7/E$11 -> 0 | F19: =F7/F$11 -> 0 | G19: =G7/G$11 -> 0 | H19: =H7/H$11 -> 0 | I19: =I7/I$11 -> 0 | ... N19: =N7/N$11 -> 0 | O19: 0 | P19: 0 | Q19: 0 | R19: 0 | S19: 0
A20: Corn 2 Crop | B20: =B8/B$11 -> 0.1082464 | C20: =C8/C$11 -> 0.10345247 | D20: =D8/D$11 -> 0.17410009 | E20: =E8/E$11 -> 0.18270848 | F20: =F8/F$11 -> 0.19021281 | G20: =G8/G$11 -> 0.19496004 | H20: =H8/H$11 -> 0.18367784 | I20: =I8/I$11 -> 0.22987389 | ... N20: =N8/N$11 -> 0.18797204 | O20: 0.16622345 | P20: 0.16622345 | Q20: 0.16622345 | R20: 0.16622345 | S20: 0.16622345
A21: Cattle | B21: =B9/B$11 -> 0 | C21: =C9/C$11 -> 0 | D21: =D9/D$11 -> 0 | E21: =E9/E$11 -> 0 | F21: =F9/F$11 -> 0 | G21: =G9/G$11 -> 0 | H21: =H9/H$11 -> 0 | I21: =I9/I$11 -> 0.0076128049 | ... N21: =N9/N$11 -> 0.0099629837 | O21: 0.0085251606 | P21: 0.0085251606 | Q21: 0.0085251606 | R21: 0.0085251606 | S21: 0.0085251606
A22: Other | B22: =B10/B$11 -> 0.042014972 | C22: =C10/C$11 -> 0.052328897 | D22: =D10/D$11 -> 0.014809415 | E22: =E10/E$11 -> 0.0090705256 | F22: =F10/F$11 -> 0.0055087564 | G22: =G10/G$11 -> 0.0041737703 | H22: =H10/H$11 -> 0.011748497 | I22: =I10/I$11 -> 0.030479287 | ... N22: =N10/N$11 -> 0.065375138 | O22: 0.071273542 | P22: 0.071273542 | Q22: 0.071273542 | R22: 0.071273542 | S22: 0.071273542
A23: Total | B23: =SUM(B16:B22) -> 1 | C23: =SUM(C16:C22) -> 1 | D23: =SUM(D16:D22) -> 1 | E23: =SUM(E16:E22) -> 1 | F23: =SUM(F16:F22) -> 1 | G23: =SUM(G16:G22) -> 1 | H23: =SUM(H16:H22) -> 1 | I23: =SUM(I16:I22) -> 1 | ... S23: =SUM(S16:S22) -> 1
A26: Ownership
A27: 80% of SLC Land Co | B27: =(B76+B82)*0.8 -> 27991.2 | C27: =(C76+C82)*0.8 -> 30612.8 | D27: =(D76+D82)*0.8 -> 28629.6 | E27: =(E76+E82)*0.8 -> 36442.4 | F27: =(F76+F82)*0.8 -> 37265.6 | G27: =(G76+G82)*0.8 -> 39578.4 | H27: =(H76+H82)*0.8 -> 39789.6 | I27: =(I76+I82)*0.8 -> 40124 | ... N27: =(N76+N82)*0.8 -> 0
A28: 50% of Joint Ventures | B28: =(B81+B75)*0.5 -> 15327.5 | C28: =(C81+C75)*0.5 -> 20993.5 | D28: =(D81+D75)*0.5 -> 24472.5 | E28: =(E81+E75)*0.5 -> 24017 | F28: =(F81+F75)*0.5 -> 22957 | G28: =(G81+G75)*0.5 -> 24033.5 | H28: =(H81+H75)*0.5 -> 25012 | I28: =(I81+I75)*0.5 -> 27910.5 | ... N28: =(N81+N75)*0.5 -> 69504.5
A29: Owned | B29: =B73+B79 -> 166538 | C29: =C73+C79 -> 173512 | D29: =D73+D79 -> 174125 | E29: =E73+E79 -> 177275 | F29: =F73+F79 -> 169175 | G29: =G73+G79 -> 173279 | H29: =H73+H79 -> 165257 | I29: =I73+I79 -> 161428 | ... N29: =N73+N79 -> 250272
A30: Total Owned | B30: =SUM(B27:B29) -> 209856.7 | C30: =SUM(C27:C29) -> 225118.3 | D30: =SUM(D27:D29) -> 227227.1 | E30: =SUM(E27:E29) -> 237734.4 | F30: =SUM(F27:F29) -> 229397.6 | G30: =SUM(G27:G29) -> 236890.9 | H30: =SUM(H27:H29) -> 230058.6 | I30: =SUM(I27:I29) -> 229462.5 | ... N30: =SUM(N27:N29) -> 319776.5 | O30: =O35*O38 -> 365855.53 | P30: =P35*P38 -> 384148.3 | Q30: =Q35*Q38 -> 403355.72 | R30: =R35*R38 -> 423523.5 | S30: =S35*S38 -> 444699.68
A31: Total Leased | B31: =B74+B80 -> 111386 | C31: =C74+C80 -> 116261 | D31: =D74+D80 -> 118400 | E31: =E74+E80 -> 122059 | F31: =F74+F80 -> 142775 | G31: =G74+G80 -> 187280 | H31: =H74+H80 -> 183550 | I31: =I74+I80 -> 195763 | ... N31: =N74+N80 -> 447917 | O31: =O35*O39 -> 519899.96 | P31: =P35*P39 -> 545894.96 | Q31: =Q35*Q39 -> 573189.7 | R31: =R35*R39 -> 601849.19 | S31: =S35*S39 -> 631941.65
A32: 20% of SLC Land Co | B32: =(B76+B82)*0.2 -> 6997.8 | C32: =(C76+C82)*0.2 -> 7653.2 | D32: =(D76+D82)*0.2 -> 7157.4 | E32: =(E76+E82)*0.2 -> 9110.6 | F32: =(F76+F82)*0.2 -> 9316.4 | G32: =(G76+G82)*0.2 -> 9894.6 | H32: =(H76+H82)*0.2 -> 9947.4 | I32: =(I76+I82)*0.2 -> 10031 | ... N32: =(N76+N82)*0.2 -> 0
A33: 50% of Joint Ventures | B33: =(B81+B75)*0.5 -> 15327.5 | C33: =(C81+C75)*0.5 -> 20993.5 | D33: =(D81+D75)*0.5 -> 24472.5 | E33: =(E81+E75)*0.5 -> 24017 | F33: =(F81+F75)*0.5 -> 22957 | G33: =(G81+G75)*0.5 -> 24033.5 | H33: =(H81+H75)*0.5 -> 25012 | I33: =(I81+I75)*0.5 -> 27910.5 | ... N33: =(N81+N75)*0.5 -> 69504.5
A34: Total Others | B34: =SUM(B32:B33) -> 22325.3 | C34: =SUM(C32:C33) -> 28646.7 | D34: =SUM(D32:D33) -> 31629.9 | E34: =SUM(E32:E33) -> 33127.6 | F34: =SUM(F32:F33) -> 32273.4 | G34: =SUM(G32:G33) -> 33928.1 | H34: =SUM(H32:H33) -> 34959.4 | I34: =SUM(I32:I33) -> 37941.5 | ... N34: =SUM(N32:N33) -> 69504.5 | O34: =O35*O40 -> 77022.216 | P34: =P35*P40 -> 80873.327 | Q34: =Q35*Q40 -> 84916.993 | R34: =R35*R40 -> 89162.843 | S34: =S35*S40 -> 93620.985
A35: Total Sum | B35: =SUM(B34,B31,B30) -> 343568 | C35: =SUM(C34,C31,C30) -> 370026 | D35: =SUM(D34,D31,D30) -> 377257 | E35: =SUM(E34,E31,E30) -> 392921 | F35: =SUM(F34,F31,F30) -> 404446 | G35: =SUM(G34,G31,G30) -> 458099 | H35: =SUM(H34,H31,H30) -> 448568 | I35: =SUM(I34,I31,I30) -> 463167 | ... N35: =SUM(N34,N31,N30) -> 837198 | O35: =N35*(1+O12) -> 962777.7 | P35: =O35*(1+P12) -> 1010916.6 | Q35: =P35*(1+Q12) -> 1061462.4 | R35: =Q35*(1+R12) -> 1114535.5 | S35: =R35*(1+S12) -> 1170262.3
A36: ▲ | C36: =C35-B35 -> 26458 | D36: =D35-C35 -> 7231 | E36: =E35-D35 -> 15664 | F36: =F35-E35 -> 11525 | G36: =G35-F35 -> 53653 | H36: =H35-G35 -> -9531 | I36: =I35-H35 -> 14599 | J36: =J35-I35 -> 208779 | ... S36: =S35-R35 -> 55726.777
A37: % Composition
A38: Owned | B38: =B30/B$35 -> 0.61081562 | C38: =C30/C$35 -> 0.60838509 | D38: =D30/D$35 -> 0.60231381 | E38: =E30/E$35 -> 0.60504376 | F38: =F30/F$35 -> 0.56718969 | G38: =G30/G$35 -> 0.51711726 | H38: =H30/H$35 -> 0.51287341 | I38: =I30/I$35 -> 0.49542066 | ... N38: =N30/N$35 -> 0.38196042 | O38: 0.38 | P38: 0.38 | Q38: 0.38 | R38: 0.38 | S38: 0.38
A39: Leased | B39: =B31/B$35 -> 0.32420365 | C39: =C31/C$35 -> 0.31419684 | D39: =D31/D$35 -> 0.31384441 | E39: =E31/E$35 -> 0.31064514 | F39: =F31/F$35 -> 0.35301375 | G39: =G31/G$35 -> 0.40881993 | H39: =H31/H$35 -> 0.40919103 | I39: =I31/I$35 -> 0.4226618 | ... N39: =N31/N$35 -> 0.53501919 | O39: 0.54 | P39: 0.54 | Q39: 0.54 | R39: 0.54 | S39: 0.54
A40: Others | B40: =B34/B$35 -> 0.064980732 | C40: =C34/C$35 -> 0.077418073 | D40: =D34/D$35 -> 0.083841784 | E40: =E34/E$35 -> 0.084311096 | F40: =F34/F$35 -> 0.079796561 | G40: =G34/G$35 -> 0.074062812 | H40: =H34/H$35 -> 0.077935564 | I40: =I34/I$35 -> 0.081917537 | ... N40: =N34/N$35 -> 0.083020385 | O40: 0.08 | P40: 0.08 | Q40: 0.08 | R40: 0.08 | S40: 0.08
A43: Expansion Capex Assumption
A44: Expansion Capex t-1 /▲ha t | C44: ='▲ PPE'!P138/C36 -> 5.0752069 | D44: ='▲ PPE'!Q138/D36 -> 11.298867 | E44: ='▲ PPE'!R138/E36 -> 5.6486035 | F44: ='▲ PPE'!S138/F36 -> -2.4384603 | G44: ='▲ PPE'!T138/G36 -> 0.55273852 | H44: ='▲ PPE'!U138/H36 -> -14.887316 | I44: ='▲ PPE'!V138/I36 -> 9.4022861 | J44: ='▲ PPE'!W138/J36 -> 0.30398309 | ... N44: ='▲ PPE'!AA138/N36 -> 7.4544875 | O44: =DCF!B15 -> 7.2 | P44: =DCF!C15 -> 7.2 | Q44: =DCF!D15 -> 7.2 | R44: =DCF!E15 -> 7.2 | S44: =DCF!F15 -> 7.2
A45: Median Ex Outliers | B45: =MEDIAN(C44:E44,I44:J44,M44:N44,G44) -> 6.5515455
A46: (Expansion Capex 2025A /▲ha 2026F)/Total ha 2025A | B46: =('▲ PPE'!AB138/'Planted Area'!O44)/N35 -> 0.22369546
...

Sheet Income by Crop
A1: Income by Crop | Y1: Yield
B2: 2013 | C2: =B2+1 -> 2014 | D2: =C2+1 -> 2015 | E2: =D2+1 -> 2016 | F2: =E2+1 -> 2017 | G2: =F2+1 -> 2018 | H2: =G2+1 -> 2019 | I2: =H2+1 -> 2020 | J2: =I2+1 -> 2021 | ... Q2: =P2+1 -> 2028 | R2: 2029 | S2: 2030 | Z2: 2013 | AA2: 2014 | AB2: 2015 | AC2: 2016 | AD2: 2017 | AE2: 2018 | AF2: 2019 | AG2: 2020 | AH2: 2021 | AI2: 2022 | AJ2: 2023 | AK2: 2024 | AL2: 2025 | AM2: 2026 | AN2: 2027 | AO2: 2028 | AP2: 2029 | AQ2: 2030
B3: A | C3: A | D3: A | E3: A | F3: A | G3: A | H3: A | I3: A | J3: A | K3: A | L3: A | M3: A | N3: A | O3: F | P3: F | Q3: F | R3: F | S3: F | Z3: A | AA3: A | AB3: A | AC3: A | AD3: A | AE3: A | AF3: A | AG3: A | AH3: A | AI3: A | AJ3: A | AK3: A | AL3: A | AM3: F | AN3: F | AO3: F | AP3: F | AQ3: F
A4: Cotton Lint Sold | Y4: Yield (ton/ha)
A5: Quantity Sold (Ton) | B5: 137437 | C5: 152796 | D5: 158183 | E5: 148429 | F5: 141126 | G5: 169673 | H5: 185374 | I5: 215965 | J5: 255993 | K5: 277222 | L5: 239303 | M5: 364238 | N5: 369328 | O5: ='Planted Area'!N4*'Income by Crop'!AM5+'Planted Area'!O5*'Income by Crop'!AM6 -> 424197.15 | P5: ='Planted Area'!O4*'Income by Crop'!AN5+'Planted Area'!P5*'Income by Crop'!AN6 -> 490879.94 | Q5: ='Planted Area'!P4*'Income by Crop'!AO5+'Planted Area'!Q5*'Income by Crop'!AO6 -> 518001.06 | R5: ='Planted Area'!Q4*'Income by Crop'!AP5+'Planted Area'!R5*'Income by Crop'!AP6 -> 546620.62 | S5: ='Planted Area'!R4*'Income by Crop'!AQ5+'Planted Area'!R5*'Income by Crop'!AQ6 -> 564319.7 | Y5: Cotton Lint 1st Crop | Z5: 1.758 | AA5: 1.522 | AB5: 1.25 | AC5: 1.619 | AD5: 1.929 | AE5: 1.685 | AF5: 1.842 | AG5: 1.913 | AH5: 1.682 | AI5: 2.019 | AJ5: 1.995 | AK5: 1.841 | AL5: 2.066 | AM5: =Z13*(1+$Z$19) -> 1.97717 | AN5: =AM5*(1+$Z$19) -> 1.9870558 | AO5: =AN5*(1+$Z$19) -> 1.9969911 | AP5: =AO5*(1+$Z$19) -> 2.0069761 | AQ5: =AP5*(1+$Z$19) -> 2.017011
A6: Net Revenue (R$ thousand) | B6: 553635 | C6: 652524 | D6: 812693 | E6: 749417 | F6: 745772 | G6: 1088621 | H6: 1212573 | I6: 1697671 | J6: 2383537 | K6: 2930972 | L6: 2189209 | M6: 3568362 | N6: 3344618 | Y6: Cotton Lint 2nd Crop | Z6: 1.545 | AA6: 1.671 | AB6: 1.389 | AC6: 1.57 | AD6: 1.622 | AE6: 1.611 | AF6: 1.749 | AG6: 1.689 | AH6: 1.305 | AI6: 1.863 | AJ6: 1.827 | AK6: 2.011 | AL6: 1.982 | AM6: =Z14*(1+$Z$19) -> 1.9497 | AN6: =AM6*(1+$Z$19) -> 1.9594485 | AO6: =AN6*(1+$Z$19) -> 1.9692457 | AP6: =AO6*(1+$Z$19) -> 1.979092 | AQ6: =AP6*(1+$Z$19) -> 1.9889874
A7: Hedhe Result (R$ thousand) | D7: -156717 | E7: -40092 | F7: 46005 | G7: -111011 | H7: -61699 | I7: -398374 | J7: -561891 | K7: -160865 | L7: 337690 | M7: 92514 | N7: 189964 | Y7: Soybean (commercial + seed) | Z7: 2.914 | AA7: 3.082 | AB7: 2.58 | AC7: 3.077 | AD7: 3.692 | AE7: 3.739 | AF7: 3.607 | AG7: 3.985 | AH7: 3.974 | AI7: 3.667 | AJ7: 3.264 | AK7: 3.961 | AL7: 4.036 | AM7: =Z15*(1+$Z$19) -> 3.772435 | AN7: =AM7*(1+$Z$19) -> 3.7912972 | AO7: =AN7*(1+$Z$19) -> 3.8102537 | AP7: =AO7*(1+$Z$19) -> 3.8293049 | AQ7: =AP7*(1+$Z$19) -> 3.8484515
A8: Hedge Adj. Net Revenue (R$ thousand) | D8: 655976 | E8: 709325 | F8: 791777 | G8: 977610 | H8: 1150874 | I8: 1299297 | J8: 1821646 | K8: 2770107 | L8: 2526899 | M8: 3660876 | N8: 3534582 | Y8: Corn 1st Crop | Z8: 8.345 | AA8: 5.708
A9: Unit Price (R$ / Ton) | B9: 4030 | C9: 4270 | D9: 4147 | E9: 4779 | F9: 5610 | G9: 5762 | H9: 6208 | I9: 6016 | J9: 7116 | K9: 9992 | L9: 10559 | M9: 10051 | N9: 9570 | O9: =Z45 -> 9228.9865 | P9: =AA45 -> 10155.092 | Q9: =AB45 -> 9910.3672 | R9: =AC45 -> 10530.986 | S9: =AD45 -> 10530.986 | Y9: Corn 2nd Crop | Z9: 7.516 | AA9: 7.029 | AB9: 5.378 | AC9: 6.877 | AD9: 5.715 | AE9: 7.095 | AF9: 7.385 | AG9: 5.88 | AH9: 6.303 | AI9: 7.588 | AJ9: 7.093 | AK9: 8.304 | AL9: 7.738 | AM9: =Z17*(1+$Z$19) -> 7.750225 | AN9: =AM9*(1+$Z$19) -> 7.7889761 | AO9: =AN9*(1+$Z$19) -> 7.827921 | AP9: =AO9*(1+$Z$19) -> 7.8670606 | AQ9: =AP9*(1+$Z$19) -> 7.9063959
A10: Total Cost (R$ thousand) | B10: -379091 | C10: -424043 | D10: -501326 | E10: -629116 | F10: -481841 | G10: -567966 | H10: -762874 | I10: -945782 | J10: -1220756 | K10: -1831639 | L10: -1636704 | M10: -2204939 | N10: -2343345 | Y10: Other
A11: Unit Cost (R$ / Ton) | B11: -2760 | C11: -2780 | D11: -3169 | E11: -4238 | F11: -3414 | G11: -3347 | H11: -4115 | I11: -4379 | J11: -4769 | K11: -6607 | L11: -6839 | M11: -6054 | N11: -6345 | O11: =(O9-O12)*-1 -> -6091.1311 | P11: =(P9-P12)*-1 -> -6702.3606 | Q11: =(Q9-Q12)*-1 -> -6540.8424 | R11: =(R9-R12)*-1 -> -6950.4508 | S11: =(S9-S12)*-1 -> -6950.4508
A12: Unit Margin (R$ / Ton) | B12: 1270 | C12: 1490 | D12: 978 | E12: 541 | F12: 2196 | G12: 2415 | H12: 2093 | I12: 1637 | J12: 2347 | K12: 3385 | L12: 3720 | M12: 3997 | N12: 3225 | O12: =O9*O13 -> 3137.8554 | P12: =P9*P13 -> 3452.7312 | Q12: =Q9*Q13 -> 3369.5249 | R12: =R9*R13 -> 3580.5353 | S12: =S9*S13 -> 3580.5353 | Y12: Average Yield (Last 3y)
A13: Margin % | B13: =B12/B9 -> 0.31513648 | C13: =C12/C9 -> 0.34894614 | D13: =D12/D9 -> 0.23583313 | E13: =E12/E9 -> 0.1132036 | F13: =F12/F9 -> 0.39144385 | G13: =G12/G9 -> 0.4191253 | H13: =H12/H9 -> 0.33714562 | I13: =I12/I9 -> 0.27210771 | ... N13: =N12/N9 -> 0.3369906 | O13: =$B$14 -> 0.34 | P13: =$B$14 -> 0.34 | Q13: =$B$14 -> 0.34 | R13: =$B$14 -> 0.34 | S13: =$B$14 -> 0.34 | Y13: Cotton Lint 1st Crop | Z13: =AVERAGE(AJ5:AL5) -> 1.9673333
A14: Margin Assumption | B14: 0.34 | Y14: Cotton Lint 2nd Crop | Z14: =AVERAGE(AJ6:AL6) -> 1.94
Y15: Soybean (commercial + seed) | Z15: =AVERAGE(AJ7:AL7) -> 3.7536667
Y16: Corn 1st Crop
A17: Cottonseed Sold | Y17: Corn 2nd Crop | Z17: =AVERAGE(AJ9:AL9) -> 7.7116667
A18: Quantity Sold (Ton) | B18: 159917 | C18: 193862 | D18: 191566 | E18: 173202 | F18: 179425 | G18: 218186 | H18: 234986 | I18: 281613 | J18: 320168 | K18: 300647 | L18: 346374 | M18: 415015 | N18: 414257 | O18: =O5*O26 -> 509036.58 | P18: =P5*P26 -> 589055.93 | Q18: =Q5*Q26 -> 621601.27 | R18: =R5*R26 -> 655944.74 | S18: =S5*S26 -> 677183.64
A19: Net Revenue (R$ thousand) | B19: 83077 | C19: 82043 | D19: 85019 | E19: 98902 | F19: 104375 | G19: 80496 | H19: 77154 | I19: 156269 | J19: 354810 | K19: 380070 | L19: 349283 | M19: 320811 | N19: 386901 | Y19: Yield Growth Assumption | Z19: 0.005
A20: Unit Price (R$ / Ton) | B20: 520 | C20: 420 | D20: 444 | E20: 571 | F20: 582 | G20: 369 | H20: 328 | I20: 555 | J20: 1108 | K20: 1264 | L20: 1008 | M20: 773 | N20: 934 | O20: =O9*O28 -> 907.76917 | P20: =P9*P28 -> 998.86149 | Q20: =Q9*Q28 -> 974.79022 | R20: =R9*R28 -> 1035.8347 | S20: =S9*S28 -> 1035.8347
A21: Total Cost (R$ thousand) | B21: -58920 | C21: -61891 | D21: -64080 | E21: -97913 | F21: -75483 | G21: -52980 | H21: -61257 | I21: -98128 | J21: -134769 | K21: -140849 | L21: -205003 | M21: -227896 | N21: -229100
A22: Unit Cost (R$ / Ton) | B22: -370 | C22: -320 | D22: -335 | E22: -565 | F22: -421 | G22: -243 | H22: -261 | I22: -348 | J22: -421 | K22: -468 | L22: -592 | M22: -549 | N22: -553 | O22: =(O20-O23)*-1 -> -644.71575 | P22: =(P20-P23)*-1 -> -709.41133 | Q22: =(Q20-Q23)*-1 -> -692.31543 | R22: =(R20-R23)*-1 -> -735.67044 | S22: =(S20-S23)*-1 -> -735.67044
A23: Unit Margin (R$ / Ton) | B23: 150 | C23: 100 | D23: 109 | E23: 6 | F23: 161 | G23: 126 | H23: 67 | I23: 207 | J23: 687 | K23: 796 | L23: 416 | M23: 224 | N23: 381 | O23: =O20*O24 -> 263.05342 | P23: =P20*P24 -> 289.45016 | Q23: =Q20*Q24 -> 282.47479 | R23: =R20*R24 -> 300.16426 | S23: =S20*S24 -> 300.16426
A24: Margin % | B24: =B23/B20 -> 0.28846154 | C24: =C23/C20 -> 0.23809524 | D24: =D23/D20 -> 0.2454955 | E24: =E23/E20 -> 0.010507881 | F24: =F23/F20 -> 0.2766323 | G24: =G23/G20 -> 0.34146341 | H24: =H23/H20 -> 0.20426829 | I24: =I23/I20 -> 0.37297297 | ... N24: =N23/N20 -> 0.40792291 | O24: =$B$25 -> 0.28978008 | P24: =$B$25 -> 0.28978008 | Q24: =$B$25 -> 0.28978008 | R24: =$B$25 -> 0.28978008 | S24: =$B$25 -> 0.28978008 | Y24: Future Contracts Implied Curve
A25: Margin Assumption | B25: =MEDIAN(B24:N24) -> 0.28978008 | Y25: Futures (05/12/26) (mm/dd/yy) | Z25: 2026 | AA25: 2027 | AB25: 2028 | AC25: 2029 | AD25: 2030
A26: Cottonseed tons/Cotton lint tons | B26: =B18/B5 -> 1.1635659 | C26: =C18/C5 -> 1.2687636 | D26: =D18/D5 -> 1.2110404 | E26: =E18/E5 -> 1.1669013 | F26: =F18/F5 -> 1.2713816 | G26: =G18/G5 -> 1.2859206 | H26: =H18/H5 -> 1.2676319 | I26: =I18/I5 -> 1.3039752 | ... N26: =N18/N5 -> 1.1216507 | O26: 1.2 | P26: 1.2 | Q26: 1.2 | R26: 1.2 | S26: 1.2
A27: Median | B27: =MEDIAN(B26:N26) -> 1.2506904 | Y27: Commodities
A28: Cottonseed Price/Cotton Lint Price | B28: =B20/B9 -> 0.12903226 | C28: =C20/C9 -> 0.098360656 | D28: =D20/D9 -> 0.10706535 | E28: =E20/E9 -> 0.11948106 | F28: =F20/F9 -> 0.10374332 | G28: =G20/G9 -> 0.064040264 | H28: =H20/H9 -> 0.052835052 | I28: =I20/I9 -> 0.092253989 | ... N28: =N20/N9 -> 0.097596656 | O28: =$B$29 -> 0.098360656 | P28: =$B$29 -> 0.098360656 | Q28: =$B$29 -> 0.098360656 | R28: =$B$29 -> 0.098360656 | S28: =$B$29 -> 0.098360656 | Y28: Cotton Lint ($/lb) | Z28: 0.8451 | AA28: 0.8593 | AB28: 0.7782 | AC28: 0.7668 | AD28: 0.7668
A29: Price/Cotton Lint Assumption | B29: =MEDIAN(B28:N28) -> 0.098360656 | Y29: Soybean ($/bu) | Z29: 12.18 | AA29: 12.13 | AB29: 11.67 | AC29: 11.47 | AD29: 11.47
Y30: Corn ($/bu) | Z30: 4.73 | AA30: 5.2025 | AB30: 5.2125 | AC30: 5.08 | AD30: 5.08
A31: Soybean Sold
A32: Quantity Sold (Ton) | B32: 394468 | C32: 537426 | D32: 634879 | E32: 539570 | F32: 746049 | G32: 842481 | H32: 898368 | I32: 899278 | J32: 1004595 | K32: 1274552 | L32: 1309363 | M32: 1013687 | N32: 1445837 | O32: ='Planted Area'!N6*AM7 -> 1602047.5 | P32: ='Planted Area'!O6*AN7 -> 1830133.8 | Q32: ='Planted Area'!P6*AO7 -> 1931248.6 | R32: ='Planted Area'!Q6*AP7 -> 2037950.1 | S32: ='Planted Area'!R6*AQ7 -> 2150546.9 | Y32: BRL/USD
A33: Net Revenue (R$ thousand) | B33: 328348 | C33: 478022 | D33: 634055 | E33: 583990 | F33: 720879 | G33: 875235 | H33: 1036218 | I33: 1291803 | J33: 1881516 | K33: 2973363 | L33: 3055726 | M33: 2092605 | N33: 2749065 | Y33: BRL/USD | Z33: 4.9535 | AA33: 5.3605 | AB33: 5.7765 | AC33: 6.2295 | AD33: 6.2295
A34: Hedhe Result (R$ thousand) | D34: -69398 | E34: 9682 | F34: 60340 | G34: -11041 | H34: -46758 | I34: -106204 | J34: -29291 | K34: 114114 | L34: 136600 | M34: 39624 | N34: 4394
A35: Hedge Adj. Net Revenue (R$ thousand) | D35: 564657 | E35: 593672 | F35: 781219 | G35: 864194 | H35: 989460 | I35: 1185599 | J35: 1852225 | K35: 3087477 | L35: 3192326 | M35: 2132229 | N35: 2753459 | Y35: Cotton Lint (brl/lb) | Z35: =Z28*Z$33 -> 4.1862028 | AA35: =AA28*AA$33 -> 4.6062777 | AB35: =AB28*AB$33 -> 4.4952723 | AC35: =AC28*AC$33 -> 4.7767806 | AD35: =AD28*AD$33 -> 4.7767806
A36: Unit Price (R$ / Ton) | B36: 830 | C36: 890 | D36: 889 | E36: 1100 | F36: 1047 | G36: 1026 | H36: 1101 | I36: 1318 | J36: 1844 | K36: 2422 | L36: 2438 | M36: 2103 | N36: 1904 | O36: =Z46 -> 2216.6576 | P36: =AA46 -> 2388.9401 | Q36: =AB46 -> 2476.7079 | R36: =AC46 -> 2625.1599 | S36: =AD46 -> 2625.1599 | Y36: Soybean (brl/bu) | Z36: =Z29*Z$33 -> 60.33363 | AA36: =AA29*AA$33 -> 65.022865 | AB36: =AB29*AB$33 -> 67.411755 | AC36: =AC29*AC$33 -> 71.452365 | AD36: =AD29*AD$33 -> 71.452365
A37: Total Cost (R$ thousand) | B37: -259742 | C37: -366835 | D37: -419781 | E37: -463229 | F37: -506506 | G37: -567844 | H37: -644331 | I37: -697641 | J37: -986071 | K37: -1449659 | L37: -1634559 | M37: -1599801 | N37: -1772371 | Y37: Corn (brl/bu) | Z37: =Z30*Z$33 -> 23.430055 | AA37: =AA30*AA$33 -> 27.888001 | AB37: =AB30*AB$33 -> 30.110006 | AC37: =AC30*AC$33 -> 31.64586 | AD37: =AD30*AD$33 -> 31.64586
A38: Unit Cost (R$ / Ton) | B38: -660 | C38: -680 | D38: -661 | E38: -859 | F38: -679 | G38: -674 | H38: -717 | I38: -776 | J38: -982 | K38: -1137 | L38: -1248 | M38: -1578 | N38: -1226 | O38: =(O36-O39)*-1 -> -1507.3271 | P38: =(P36-P39)*-1 -> -1624.4792 | Q38: =(Q36-Q39)*-1 -> -1684.1614 | R38: =(R36-R39)*-1 -> -1785.1087 | S38: =(S36-S39)*-1 -> -1785.1087
A39: Unit Margin (R$ / Ton) | B39: 170 | C39: 210 | D39: 228 | E39: 241 | F39: 368 | G39: 352 | H39: 384 | I39: 542 | J39: 862 | K39: 1285 | L39: 1190 | M39: 525 | N39: 678 | O39: =O36*O40 -> 709.33042 | P39: =P36*P40 -> 764.46082 | Q39: =Q36*Q40 -> 792.54652 | R39: =R36*R40 -> 840.05116 | S39: =S36*S40 -> 840.05116
A40: Margin % | B40: =B39/B36 -> 0.20481928 | C40: =C39/C36 -> 0.23595506 | D40: =D39/D36 -> 0.25646794 | E40: =E39/E36 -> 0.21909091 | F40: =F39/F36 -> 0.35148042 | G40: =G39/G36 -> 0.34307992 | H40: =H39/H36 -> 0.34877384 | I40: =I39/I36 -> 0.41122914 | ... N40: =N39/N36 -> 0.35609244 | O40: =$B$42 -> 0.32 | P40: =$B$42 -> 0.32 | Q40: =$B$42 -> 0.32 | R40: =$B$42 -> 0.32 | S40: =$B$42 -> 0.32 | Y40: lb/ton | Z40: 2204.62
...

Sheet CoE
A1: Debt
B2: 2013 | C2: 2014 | D2: 2015 | E2: 2016 | F2: 2017 | G2: 2018 | H2: 2019 | I2: 2020 | J2: 2021 | K2: 2022 | L2: 2023 | M2: 2024 | N2: 2025 | O2: 2026 | P2: 2027 | Q2: 2028 | R2: 2029 | S2: 2030
B3: A | C3: A | D3: A | E3: A | F3: A | G3: A | H3: A | I3: A | J3: A | K3: A | L3: A | M3: A | N3: A | O3: F | P3: F | Q3: F | R3: F | S3: F
A4: Loans and Financing | B4: ='Balance Sheet'!B53+'Balance Sheet'!B39 -> 1170289 | C4: ='Balance Sheet'!C53+'Balance Sheet'!C39 -> 1331976 | D4: ='Balance Sheet'!D53+'Balance Sheet'!D39 -> 1878877 | E4: ='Balance Sheet'!E53+'Balance Sheet'!E39 -> 1901245 | F4: ='Balance Sheet'!F53+'Balance Sheet'!F39 -> 1589174 | G4: ='Balance Sheet'!G53+'Balance Sheet'!G39 -> 1605071 | H4: ='Balance Sheet'!H53+'Balance Sheet'!H39 -> 1859766 | I4: ='Balance Sheet'!I53+'Balance Sheet'!I39 -> 2417283 | ... N4: ='Balance Sheet'!N53+'Balance Sheet'!N39 -> 7728284 | O4: =N4*(1+O5)+O15 -> 7728284 | P4: =O4*(1+P5)+P15 -> 7728284 | Q4: =P4*(1+Q5)+Q15 -> 7728284 | R4: =Q4*(1+R5)+R15 -> 7728284 | S4: =R4*(1+S5)+S15 -> 7728284
A5: ▲% | C5: =(C4-B4)/B4 -> 0.13815989 | D5: =(D4-C4)/C4 -> 0.41059373 | E5: =(E4-D4)/D4 -> 0.011904984 | F5: =(F4-E4)/E4 -> -0.16414034 | G5: =(G4-F4)/F4 -> 0.01000331 | H5: =(H4-G4)/G4 -> 0.15868145 | I5: =(I4-H4)/H4 -> 0.29977804 | J5: =(J4-I4)/I4 -> 0.070523807 | ... N5: =(N4-M4)/M4 -> 0.38044414
A6: Geomean | B6: {=GEOMEAN(C5:N5+1)-1} -> 0.17035019
A7: {='Income Statement'!A52:N52} -> Interest | B7: -36171 | C7: -68098 | D7: 35859 | E7: -194915 | F7: -94074 | G7: -77661 | H7: -101197 | I7: -53636 | J7: -98269 | K7: -459171 | L7: -454331 | M7: -517399 | N7: -827999 | O7: =N4*O8 -> -826926.39 | P7: =O4*P8 -> -826926.39 | Q7: =P4*Q8 -> -826926.39 | R7: =Q4*R8 -> -826926.39 | S7: =R4*S8 -> -826926.39
A8: % Rate | B8: =B7/B4 -> -0.03090775 | C8: =C7/C4 -> -0.051125546 | D8: =D7/D4 -> 0.019085337 | E8: =E7/E4 -> -0.10251966 | F8: =F7/F4 -> -0.05919679 | G8: =G7/G4 -> -0.048384776 | H8: =H7/H4 -> -0.054413835 | I8: =I7/I4 -> -0.022188548 | ... N8: =N7/N4 -> -0.10713879 | O8: =$B$10*-1 -> -0.107 | P8: =$B$10*-1 -> -0.107 | Q8: =$B$10*-1 -> -0.107 | R8: =$B$10*-1 -> -0.107 | S8: =$B$10*-1 -> -0.107
A10: Interest Rate | B10: 0.107
A12: Tax Rate | B12: ='Income Statement'!B65/'Income Statement'!B61*-1 -> 0.23076984 | C12: ='Income Statement'!C65/'Income Statement'!C61*-1 -> 0.21251586 | D12: ='Income Statement'!D65/'Income Statement'!D61*-1 -> 0.27291874 | E12: ='Income Statement'!E65/'Income Statement'!E61*-1 -> 4.7589522 | F12: ='Income Statement'!F65/'Income Statement'!F61*-1 -> 0.26293539 | G12: ='Income Statement'!G65/'Income Statement'!G61*-1 -> 0.3052227 | H12: ='Income Statement'!H65/'Income Statement'!H61*-1 -> 0.24024627 | I12: ='Income Statement'!I65/'Income Statement'!I61*-1 -> 0.25861313 | ... N12: ='Income Statement'!N65/'Income Statement'!N61*-1 -> 0.20802578
A13: Average tax rate | B13: =AVERAGE(B12:D12,F12:L12,N12) -> 0.25031248
A15: New Debt | O15: =IF(DCF!B22<0,DCF!B22*-1,0) -> 0 | P15: =IF(DCF!C22<0,DCF!C22*-1,0) -> 0 | Q15: =IF(DCF!D22<0,DCF!D22*-1,0) -> 0 | R15: =IF(DCF!E22<0,DCF!E22*-1,0) -> 0 | S15: =IF(DCF!F22<0,DCF!F22*-1,0) -> 0
A18: Risk Free (US 10y Treasury 2026) | B18: 0.04489
A19: Risk Premium (Damodaran) | B19: 0.0423
A20: EMBI+ Brazil | B20: 0.0228
A23: Debt Weight | B23: =1-B24 -> 0.35385027 | C23: =1-C24 -> 0.35757899 | D23: =1-D24 -> 0.43990059 | E23: =1-E24 -> 0.41968875 | F23: =1-F24 -> 0.37035041 | G23: =1-G24 -> 0.36479127 | H23: =1-H24 -> 0.38390802 | I23: =1-I24 -> 0.43410331 | ... S23: =1-S24 -> 0.52976332
A24: Equity Weight | B24: ='Balance Sheet'!B72/(B4+'Balance Sheet'!B72) -> 0.64614973 | C24: ='Balance Sheet'!C72/(C4+'Balance Sheet'!C72) -> 0.64242101 | D24: ='Balance Sheet'!D72/(D4+'Balance Sheet'!D72) -> 0.56009941 | E24: ='Balance Sheet'!E72/(E4+'Balance Sheet'!E72) -> 0.58031125 | F24: ='Balance Sheet'!F72/(F4+'Balance Sheet'!F72) -> 0.62964959 | G24: ='Balance Sheet'!G72/(G4+'Balance Sheet'!G72) -> 0.63520873 | H24: ='Balance Sheet'!H72/(H4+'Balance Sheet'!H72) -> 0.61609198 | I24: ='Balance Sheet'!I72/(I4+'Balance Sheet'!I72) -> 0.56589669 | ... S24: ='Balance Sheet'!S72/(S4+'Balance Sheet'!S72) -> 0.47023668
A27: Leveraged Beta | O27: =$B$28*(1+(1-'Income Statement'!$B$67)*(O23/O24)) -> 1.6217365 | P27: =$B$28*(1+(1-'Income Statement'!$B$67)*(P23/P24)) -> 1.5922641 | Q27: =$B$28*(1+(1-'Income Statement'!$B$67)*(Q23/Q24)) -> 1.561692 | R27: =$B$28*(1+(1-'Income Statement'!$B$67)*(R23/R24)) -> 1.5275302 | S27: =$B$28*(1+(1-'Income Statement'!$B$67)*(S23/S24)) -> 1.4944026
A28: Farming/Agriculture Damodaran Unleveraged Beta | B28: 0.81
A30: Cost of Equity | O30: =$B$18+O27*$B$19+$B$20 -> 0.13628945 | P30: =$B$18+P27*$B$19+$B$20 -> 0.13504277 | Q30: =$B$18+Q27*$B$19+$B$20 -> 0.13374957 | R30: =$B$18+R27*$B$19+$B$20 -> 0.13230453 | S30: =$B$18+S27*$B$19+$B$20 -> 0.13090323

Sheet Balance Sheet
A1: Balance Sheet
B2: 2013 | C2: 2014 | D2: 2015 | E2: 2016 | F2: 2017 | G2: 2018 | H2: 2019 | I2: 2020 | J2: 2021 | K2: 2022 | L2: 2023 | M2: 2024 | N2: 2025 | O2: 2026 | P2: 2027 | Q2: 2028 | R2: 2029 | S2: 2030
B3: A | C3: A | D3: A | E3: A | F3: A | G3: A | H3: A | I3: A | J3: A | K3: A | L3: A | M3: A | N3: A | O3: F | P3: F | Q3: F | R3: F | S3: F
A4: Cash and Cash Equivalents | B4: 392977 | C4: 371962 | D4: 701460 | E4: 1064506 | F4: 749328 | G4: 642736 | H4: 884769 | I4: 1604053 | J4: 139780 | K4: 1235775 | L4: 1613703 | M4: 1979575 | N4: 2647586
A5: Accounts Receivable | B5: 62438 | C5: 120663 | D5: 176691 | E5: 73392 | F5: 168128 | G5: 131546 | H5: 178405 | I5: 207283 | J5: 147414 | K5: 174291 | L5: 143694 | M5: 251157 | N5: 248085
A6: Advance to suppliers | B6: 2550 | C6: 5200 | D6: 4438 | E6: 1728 | F6: 9017 | G6: 8520 | H6: 2443 | I6: 3580 | J6: 29502 | K6: 14924 | L6: 9098 | M6: 30551 | N6: 35652
A7: Inventory | B7: 514819 | C7: 622101 | D7: 728192 | E7: 486425 | F7: 569524 | G7: 868522 | H7: 1071354 | I7: 1301082 | J7: 2806365 | K7: 3343980 | L7: 3656261 | M7: 3780562 | N7: 3722611
A8: Biological Assets | B8: 378481 | C8: 374372 | D8: 423705 | E8: 521174 | F8: 522997 | G8: 705390 | H8: 780589 | I8: 891804 | J8: 1690969 | K8: 1799576 | L8: 1488540 | M8: 1785392 | N8: 2350421
A9: Recoverable Taxes | B9: 78361 | C9: 98566 | D9: 89321 | E9: 66727 | F9: 45908 | G9: 86943 | H9: 41943 | I9: 39447 | J9: 126936 | K9: 139817 | L9: 127236 | M9: 207078 | N9: 290925
A10: Titles to be received | B10: 10313 | C10: 5474 | D10: 4444 | E10: 7948 | F10: 123657 | G10: 66342 | H10: 71657 | I10: 31207 | J10: 21919 | K10: 25852 | L10: 27590 | M10: 23176 | N10: 84366
A11: Operations with Derivatives | B11: 5278 | C11: 8936 | D11: 26639 | E11: 99963 | F11: 47140 | G11: 60222 | H11: 34008 | I11: 98587 | J11: 107676 | K11: 272728 | L11: 265314 | M11: 286904 | N11: 408226
A12: Other Accounts Receivable | B12: 4754 | C12: 3456 | D12: 15812 | E12: 2507 | F12: 3916 | G12: 5290 | H12: 11412 | I12: 6217 | J12: 23977 | K12: 15012 | L12: 19980 | M12: 15836 | N12: 8864
A13: Prepaid expenses | B13: 3793 | C13: 2712 | D13: 5469 | E13: 7721 | F13: 8354 | G13: 5060 | H13: 14030 | I13: 17141 | J13: 14275 | K13: 10183 | L13: 10982 | M13: 27245 | N13: 47153
A14: Others | B14: 0 | C14: 0 | D14: 677 | E14: 77 | F14: 2370 | G14: 1449 | H14: 189 | I14: 971 | J14: 573 | K14: 545 | L14: 3640 | M14: 2397 | N14: 1578
A16: Current Assets | B16: =SUM(B4:B14) -> 1453764 | C16: =SUM(C4:C14) -> 1613442 | D16: =SUM(D4:D14) -> 2176848 | E16: =SUM(E4:E14) -> 2332168 | F16: =SUM(F4:F14) -> 2250339 | G16: =SUM(G4:G14) -> 2582020 | H16: =SUM(H4:H14) -> 3090799 | I16: =SUM(I4:I14) -> 4201372 | ... N16: =SUM(N4:N14) -> 9845467
A18: Recoverable Taxes | B18: 20726 | C18: 31576 | D18: 51954 | E18: 55834 | F18: 62841 | G18: 82895 | H18: 122469 | I18: 111203 | J18: 152690 | K18: 204094 | L18: 233688 | M18: 269972 | N18: 397746
A19: Deferred Income Tax and social contribution | B19: 3924 | C19: 8358 | D19: 23509 | E19: 26265 | F19: 18760 | G19: 17168 | H19: 22517 | I19: 20480 | J19: 405662 | K19: 281819 | L19: 254080 | M19: 351448 | N19: 295230
A20: Operations with Derivatives | B20: 1938 | C20: 1329 | D20: 101852 | E20: 48648 | F20: 23766 | G20: 8770 | H20: 11328 | I20: 146785 | J20: 183607 | K20: 61677 | L20: 19746 | M20: 298888 | N20: 181721
A21: Advance to suppliers | B21: 68583 | C21: 71218 | D21: 76430 | E21: 71542 | F21: 57763 | G21: 46176 | H21: 30241 | I21: 59814 | J21: 74202 | K21: 79805 | L21: 75410 | M21: 30288 | N21: 32755
A22: Investments valued at fair value | B22: 0 | C22: 0 | D22: 0 | E22: 0 | F22: 0 | G22: 0 | H22: 650 | I22: 663 | J22: 684 | K22: 747 | L22: 1115 | M22: 1587 | N22: 1782
A23: Titles to be received | B23: 8594 | C23: 7956 | D23: 7464 | E23: 0 | F23: 0 | G23: 0 | H23: 5248 | I23: 2700 | J23: 26962 | K23: 31650 | L23: 0 | M23: 521 | N23: 107588
A24: Prepaid expenses | B24: 5796 | C24: 1665 | D24: 2830 | E24: 3777 | F24: 2567 | G24: 2659 | H24: 528 | I24: 437 | J24: 19 | K24: 458 | L24: 1798 | M24: 668 | N24: 10662
A25: Other credits | B25: 1684 | C25: 4760 | D25: 11991 | E25: 17309 | F25: 17029 | G25: 15643 | H25: 7945 | I25: 13705 | J25: 19770 | K25: 40174 | L25: 49656 | M25: 61078 | N25: 60094
A27: Non-Current Assets | B27: =SUM(B18:B25) -> 111245 | C27: =SUM(C18:C25) -> 126862 | D27: =SUM(D18:D25) -> 276030 | E27: =SUM(E18:E25) -> 223375 | F27: =SUM(F18:F25) -> 182726 | G27: =SUM(G18:G25) -> 173311 | H27: =SUM(H18:H25) -> 200926 | I27: =SUM(I18:I25) -> 355787 | ... N27: =SUM(N18:N25) -> 1087578
A29: Investment Property | B29: 4461 | C29: 5848 | D29: 93350 | E29: 210644 | F29: 202243 | G29: 209082 | H29: 0 | I29: 0 | J29: 333269 | K29: 385817 | L29: 430889 | M29: 58683 | N29: 53182
A30: Right of use Assets | B30: 0 | C30: 0 | D30: 0 | E30: 0 | F30: 0 | G30: 0 | H30: 555031 | I30: 828496 | J30: 3042185 | K30: 2881262 | L30: 2885337 | M30: 2567191 | N30: 2763422
A31: Fixed asset | B31: 2685343 | C31: 2747811 | D31: 2760438 | E31: 2683944 | F31: 2647977 | G31: 2784265 | H31: 3095999 | I31: 3168738 | J31: 3398063 | K31: 3733112 | L31: 4395692 | M31: 5417528 | N31: 7111885
A32: Intangible | B32: 6264 | C32: 4671 | D32: 2967 | E32: 3245 | F32: 10400 | G32: 6853 | H32: 15363 | I32: 35290 | J32: 118184 | K32: 131473 | L32: 137977 | M32: 121776 | N32: 473493
A34: Total Fixed Assets | B34: =SUM(B29:B32) -> 2696068 | C34: =SUM(C29:C32) -> 2758330 | D34: =SUM(D29:D32) -> 2856755 | E34: =SUM(E29:E32) -> 2897833 | F34: =SUM(F29:F32) -> 2860620 | G34: =SUM(G29:G32) -> 3000200 | H34: =SUM(H29:H32) -> 3666393 | I34: =SUM(I29:I32) -> 4032524 | ... N34: =SUM(N29:N32) -> 10401982
A36: Total Assets | B36: =SUM(B34,B27,B16) -> 4261077 | C36: =SUM(C34,C27,C16) -> 4498634 | D36: =SUM(D34,D27,D16) -> 5309633 | E36: =SUM(E34,E27,E16) -> 5453376 | F36: =SUM(F34,F27,F16) -> 5293685 | G36: =SUM(G34,G27,G16) -> 5755531 | H36: =SUM(H34,H27,H16) -> 6958118 | I36: =SUM(I34,I27,I16) -> 8589683 | ... N36: =SUM(N34,N27,N16) -> 21335027
A38: Suppliers | B38: 236217 | C38: 312759 | D38: 398860 | E38: 439735 | F38: 424041 | G38: 703564 | H38: 922000 | I38: 1101769 | J38: 1009194 | K38: 1564582 | L38: 1258175 | M38: 1888315 | N38: 2004563
A39: Loans and Financing | B39: 692418 | C39: 780739 | D39: 931732 | E39: 1155641 | F39: 860976 | G39: 738712 | H39: 699515 | I39: 377547 | J39: 669735 | K39: 1281537 | L39: 1413552 | M39: 1685130 | N39: 1591681
A40: Taxes and Contributions | B40: 18605 | C40: 13926 | D40: 6702 | E40: 7995 | F40: 28414 | G40: 24656 | H40: 57510 | I40: 57186 | J40: 57832 | K40: 207688 | L40: 109026 | M40: 17962 | N40: 153593
A41: Social and Labor Obligations | B41: 8875 | C41: 10344 | D41: 13763 | E41: 15308 | F41: 62701 | G41: 63007 | H41: 54572 | I41: 79989 | J41: 148613 | K41: 149756 | L41: 135279 | M41: 111208 | N41: 133955
A42: Advanced of customers | B42: 25029 | C42: 53200 | D42: 110401 | E42: 19285 | F42: 98652 | G42: 42163 | H42: 33289 | I42: 68264 | J42: 568043 | K42: 238942 | L42: 354070 | M42: 531616 | N42: 450508
A43: Operations with Derivatives | B43: 31433 | C43: 51651 | D43: 120544 | E43: 56604 | F43: 42583 | G43: 139866 | H43: 55230 | I43: 358969 | J43: 394582 | K43: 139585 | L43: 113012 | M43: 794133 | N43: 159003
A44: Securities Payable | B44: 126494 | C44: 49689 | D44: 75564 | E44: 81813 | F44: 17543 | G44: 11567 | H44: 12273 | I44: 12273 | J44: 93775 | K44: 86102 | L44: 53899 | M44: 612844 | N44: 590158
A45: Provisions of Taxes, Environmental and Labor Risks | B45: 16587 | C45: 17724 | D45: 20415 | E45: 15022 | F45: 2446 | G45: 2397 | H45: 4121 | I45: 5429 | J45: 32002 | K45: 38257 | L45: 13594 | M45: 13741 | N45: 3623
A46: Dividends to be paid | B46: 23923 | C46: 17758 | D46: 29100 | E46: 7112 | F46: 83598 | G46: 91804 | H46: 73759 | I46: 86332 | J46: 269803 | K46: 302370 | L46: 197404 | M46: 120857 | N46: 9441
A47: Leasing liabilities with third parties | B47: 0 | C47: 0 | D47: 0 | E47: 0 | F47: 0 | G47: 0 | H47: 114567 | I47: 162258 | J47: 511932 | K47: 523573 | L47: 298644 | M47: 248995 | N47: 249790
...

Sheet ▲ PPE
A1: (R$ thud) | B1: Category | C1: Opening Balance | D1: Business Combinations | E1: Additions | F1: Disposals | G1: Transfers | H1: Reclassifications | I1: Fair Value Realization | J1: Depreciation | K1: Closing Balance | O1: Capex | P1: 2013 | Q1: 2014 | R1: 2015 | S1: 2016 | T1: 2017 | U1: 2018 | V1: 2019 | W1: 2020 | X1: 2021 | Y1: 2022 | Z1: 2023 | AA1: 2024 | AB1: 2025 | AC1: 2026 | AD1: 2027 | AE1: 2028 | AF1: 2029 | AG1: 2030
A2: 2025 | B2: Farmland | C2: 2466270 | D2: - | E2: 842051 | F2: - | G2: -9000 | H2: 16179 | I2: - | J2: - | K2: =SUM(C2:J2) -> 3315500 | O2: Farmland | P2: {=_xlfn._xlws.FILTER($E:$E,$A:$A=P1)} -> 53468 | Q2: {=_xlfn._xlws.FILTER($E:$E,$A:$A=Q1)} -> 1321 | R2: {=_xlfn._xlws.FILTER($E:$E,$A:$A=R1)} -> 85579 | S2: {=_xlfn._xlws.FILTER($E:$E,$A:$A=S1)} -> 2 | T2: {=_xlfn._xlws.FILTER($E:$E,$A:$A=T1)} -> 4400 | U2: {=_xlfn._xlws.FILTER($E:$E,$A:$A=U1)} -> 2005 | V2: {=_xlfn._xlws.FILTER($E:$E,$A:$A=V1)} -> 3070 | W2: {=_xlfn._xlws.FILTER($E:$E,$A:$A=W1)} -> 102 | ... AB2: {=_xlfn._xlws.FILTER($E:$E,$A:$A=AB1)} -> 842051
A3: 2025 | B3: Soil Improvement and Development | C3: 790417 | D3: 117615 | E3: 305163 | F3: -6314 | G3: 475 | H3: - | I3: 62 | J3: -155305 | K3: =SUM(C3:J3) -> 1052113 | O3: Soil Improvement and Development | P3: 64018 | Q3: 76203 | R3: 35514 | S3: 26439 | T3: 32027 | U3: 48225 | V3: 46403 | W3: 76166 | X3: 153372 | Y3: 187328 | Z3: 197866 | AA3: 288411 | AB3: 305163
A4: 2025 | B4: Buildings and Improvements | C4: 632288 | D4: 60973 | E4: 966 | F4: -71 | G4: 142569 | H4: 81 | I4: -18 | J4: -39493 | K4: =SUM(C4:J4) -> 797295 | O4: Buildings and Improvements | P4: 475 | Q4: 680 | R4: 201 | S4: 104 | T4: 1779 | U4: 2931 | V4: 1931 | W4: 1373 | X4: 1060 | Y4: 2442 | Z4: 34878 | AA4: 1609 | AB4: 966
A5: 2025 | B5: Agricultural Equipment and Industrial Facilities | C5: 1048834 | D5: 148888 | E5: 209512 | F5: -10620 | G5: 150853 | H5: 861 | I5: -13779 | J5: -124902 | K5: =SUM(C5:J5) -> 1409647 | O5: Agricultural Equipment and Industrial Facilities | P5: 80753 | Q5: 51291 | R5: 32761 | S5: 25879 | T5: 37060 | U5: 114969 | V5: 106099 | W5: 89666 | X5: 171752 | Y5: 230228 | Z5: 133736 | AA5: 168570 | AB5: 209512
A6: 2025 | B6: Vehicles | C6: 117575 | D6: 14700 | E6: 3850 | F6: -350 | G6: 239 | H6: - | I6: -1691 | J6: -10486 | K6: =SUM(C6:J6) -> 123837 | O6: Vehicles | P6: 7508 | Q6: 3456 | R6: 2912 | S6: 1026 | T6: 3440 | U6: 19315 | V6: 11554 | W6: 2636 | X6: 3471 | Y6: 4797 | Z6: 7419 | AA6: 96127 | AB6: 3850
A7: 2025 | B7: Furniture and Fixtures | C7: 25855 | D7: 720 | E7: 6164 | F7: -246 | G7: 579 | H7: 45 | I7: -100 | J7: -3917 | K7: =SUM(C7:J7) -> 29100 | O7: Furniture and Fixtures | P7: 991 | Q7: 1062 | R7: 902 | S7: 1484 | T7: 987 | U7: 2601 | V7: 2149 | W7: 3033 | X7: 3016 | Y7: 4710 | Z7: 6884 | AA7: 7810 | AB7: 6164
A8: 2025 | B8: Office Equipment and Installations | C8: 41139 | D8: -942 | E8: 8681 | F8: -262 | G8: 877 | H8: 30 | I8: - | J8: -13652 | K8: =SUM(C8:J8) -> 35871 | O8: Office Equipment and Installations | P8: 1672 | Q8: 2364 | R8: 1537 | S8: 1199 | T8: 1907 | U8: 4632 | V8: 6581 | W8: 8863 | X8: 16259 | Y8: 13201 | Z8: 15553 | AA8: 12283 | AB8: 8681
A9: 2025 | B9: Other | C9: 14950 | D9: 81 | E9: 4839 | F9: -78 | G9: 474 | H9: -1464 | I9: - | J9: -290 | K9: =SUM(C9:J9) -> 18512 | O9: Other | P9: 373 | Q9: 358 | R9: 233 | S9: 149 | T9: 213 | U9: 593 | V9: 890 | W9: 763 | X9: 594 | Y9: 910 | Z9: 1116 | AA9: 2637 | AB9: 4839
A10: 2025 | B10: Advances to Suppliers | O10: Advances to Suppliers | P10: 16677 | Q10: 3252 | R10: - | S10: 0 | T10: 0 | U10: 0 | V10: 0 | W10: 0 | X10: 0 | Y10: 0 | Z10: 0 | AA10: 0 | AB10: 0
A11: 2025 | B11: Construction in Progress | C11: 280200 | E11: 348998 | F11: - | G11: -287066 | H11: -12122 | I11: - | J11: - | K11: =SUM(C11:J11) -> 330010 | O11: Construction in Progress | P11: 36808 | Q11: 55479 | R11: 39378 | S11: 19725 | T11: 48641 | U11: 72483 | V11: 86519 | W11: 27170 | X11: 75039 | Y11: 142892 | Z11: 245249 | AA11: 463647 | AB11: 348998
A12: 2025 | B12: Bearer Plants | O12: Bearer Plants | P12: 0 | Q12: 0 | R12: - | S12: - | T12: - | U12: - | V12: - | W12: 0 | X12: 0 | Y12: 0 | Z12: 0 | AA12: 0 | AB12: 0
A13: 2025 | B13: Total | C13: =SUM(C2:C11) -> 5417528 | D13: =SUM(D2:D11) -> 342035 | E13: =SUM(E2:E11) -> 1730224 | F13: =SUM(F2:F11) -> -17941 | G13: =SUM(G2:G11) -> 0 | H13: =SUM(H2:H11) -> 3610 | I13: =SUM(I2:I11) -> -15526 | J13: =SUM(J2:J11) -> -348045 | K13: =SUM(K2:K11) -> 7111885 | O13: Total | P13: 262743 | Q13: 195466 | R13: 199017 | S13: 76007 | T13: 130454 | U13: 267754 | V13: 265196 | W13: 209772 | X13: 424884 | Y13: 586693 | Z13: 1008406 | AA13: 1092004 | AB13: 1730224
O14: =_xlfn.UNICHAR(916) -> Δ | Q14: =(Q13-P13)/P13 -> -0.2560563 | R14: =(R13-Q13)/Q13 -> 0.018166842 | S14: =(S13-R13)/R13 -> -0.6180879 | T14: =(T13-S13)/S13 -> 0.71634192 | U14: =(U13-T13)/T13 -> 1.0524783 | V14: =(V13-U13)/U13 -> -0.0095535454 | W14: =(W13-V13)/V13 -> -0.20899259 | X14: =(X13-W13)/W13 -> 1.0254562 | ... AB14: =(AB13-AA13)/AA13 -> 0.58444841
A15: 2024 | B15: Farmland | C15: 2083280 | E15: 50910 | F15: -37844 | G15: 3209 | H15: 366715 | I15: - | J15: - | K15: =SUM(C15:J15) -> 2466270
A16: 2024 | B16: Soil Improvement and Development | C16: 613121 | E16: 288411 | F16: - | G16: -1864 | H16: 12191 | I16: - | J16: -121442 | K16: =SUM(C16:J16) -> 790417 | O16: Initial PPE | P16: {=_xlfn._xlws.FILTER($C:$C,($A:$A=P$1)*($B:$B="Total"))} -> 2594571 | Q16: {=_xlfn._xlws.FILTER($C:$C,($A:$A=Q$1)*($B:$B="Total"))} -> 2685343 | R16: {=_xlfn._xlws.FILTER($C:$C,($A:$A=R$1)*($B:$B="Total"))} -> 2753659 | S16: {=_xlfn._xlws.FILTER($C:$C,($A:$A=S$1)*($B:$B="Total"))} -> 2764677 | T16: {=_xlfn._xlws.FILTER($C:$C,($A:$A=T$1)*($B:$B="Total"))} -> 2686064 | U16: {=_xlfn._xlws.FILTER($C:$C,($A:$A=U$1)*($B:$B="Total"))} -> 2647977 | V16: {=_xlfn._xlws.FILTER($C:$C,($A:$A=V$1)*($B:$B="Total"))} -> 2784265 | W16: {=_xlfn._xlws.FILTER($C:$C,($A:$A=W$1)*($B:$B="Total"))} -> 2878989 | ... AB16: {=_xlfn._xlws.FILTER($C:$C,($A:$A=AB$1)*($B:$B="Total"))} -> 5417528
A17: 2024 | B17: Buildings and Improvements | C17: 533164 | E17: 1609 | F17: -150 | G17: 122009 | H17: 6549 | I17: - | J17: -30893 | K17: =SUM(C17:J17) -> 632288 | O17: Ending PPE | P17: {=_xlfn._xlws.FILTER($K:$K,($A:$A=P$1)*($B:$B="Total"))} -> 2685343 | Q17: {=_xlfn._xlws.FILTER($K:$K,($A:$A=Q$1)*($B:$B="Total"))} -> 2747811 | R17: {=_xlfn._xlws.FILTER($K:$K,($A:$A=R$1)*($B:$B="Total"))} -> 2764677 | S17: {=_xlfn._xlws.FILTER($K:$K,($A:$A=S$1)*($B:$B="Total"))} -> 2686064 | T17: {=_xlfn._xlws.FILTER($K:$K,($A:$A=T$1)*($B:$B="Total"))} -> 2647977 | U17: {=_xlfn._xlws.FILTER($K:$K,($A:$A=U$1)*($B:$B="Total"))} -> 2784265 | V17: {=_xlfn._xlws.FILTER($K:$K,($A:$A=V$1)*($B:$B="Total"))} -> 2878993 | W17: {=_xlfn._xlws.FILTER($K:$K,($A:$A=W$1)*($B:$B="Total"))} -> 2944444 | ... AB17: {=_xlfn._xlws.FILTER($K:$K,($A:$A=AB$1)*($B:$B="Total"))} -> 7111885
A18: 2024 | B18: Agricultural Equipment and Industrial Facilities | C18: 862913 | E18: 168570 | F18: -13851 | G18: 181295 | H18: -1623 | I18: -17173 | J18: -131297 | K18: =SUM(C18:J18) -> 1048834 | O18: =_xlfn.UNICHAR(916)&"% Ending PPE" -> Δ% Ending PPE | P18: =(P17-P16)/P16 -> 0.03498536 | Q18: =(Q17-P17)/P17 -> 0.023262578 | R18: =(R17-Q17)/Q17 -> 0.0061379767 | S18: =(S17-R17)/R17 -> -0.028434786 | T18: =(T17-S17)/S17 -> -0.014179483 | U18: =(U17-T17)/T17 -> 0.051468725 | V18: =(V17-U17)/U17 -> 0.034022624 | W18: =(W17-V17)/V17 -> 0.022733991 | X18: =(X17-W17)/W17 -> 0.15405931 | ... AB18: =(AB17-AA17)/AA17 -> 0.31275464
